<?xml version="1.0"?>
<robot name="smartcar" xmlns:xacro="http://ros.org/wiki/xacro">
  <property name="M_PI" value="3.14159"/>

  <!-- Macro for SmartCar body. Including Gazebo extensions, but does not include Kinect -->
  <include filename="$(find smartcar_description)/urdf/gazebo.urdf.xacro"/>

  <property name="base_x" value="0.33" />
  <property name="base_y" value="0.33" />

  <xacro:macro name="smartcar_body">


	<link name="base_link">
	<inertial>
      <origin xyz="0 0 0.315"/>
      <mass value="100.0" />
      <inertia ixx="1.0" ixy="0.0" ixz="0.0" iyy="1.0" iyz="0.0" izz="1.0"/>
    </inertial>
    <visual>
      <geometry>
        <box size="1.505 1 0.57"/>
      </geometry>
	  <origin rpy="0 0 0" xyz="0 0 0.315"/>
      <material name="blue">
	  <color rgba="1 .8 0 1"/>
      </material>
   </visual>
   <collision>
      <origin rpy="0 0 0" xyz="0 0 0.315"/>
      <geometry>
        <box size="1.505 1 0.57" />
      </geometry>
    </collision>
  </link>


 <link name="left_front_wheel">
	<inertial>
      <origin  xyz="0.5 0.45 0.1"/>
      <mass value="1" />
       <inertia ixx="1.0" ixy="0.0" ixz="0.0" iyy="1.0" iyz="0.0" izz="1.0"/>
    </inertial>
    <visual>
      <geometry>
        <cylinder length=".1" radius="0.1"/>
      </geometry>
      <material name="black">
        <color rgba="0 0 0 1"/>
      </material>
    </visual>
    <collision>
      <origin rpy="0 1.57075 1.57075" xyz="0.5 0.45 0.1"/>
      <geometry>
         <cylinder length=".1" radius="0.1"/>
      </geometry>
    </collision>
  </link>

  <joint name="left_front_wheel_joint" type="continuous">
    <axis xyz="0 0 1"/>
    <parent link="base_link"/>
    <child link="left_front_wheel"/>
    <origin rpy="0 1.57075 1.57075" xyz="0.5 0.45 0.1"/>
    <limit effort="100" velocity="100"/>
    <joint_properties damping="0.0" friction="0.0"/>
  </joint>

  <link name="right_front_wheel">
	<inertial>
      <origin xyz="0.5 -0.45 0.1"/>
      <mass value="1" />
       <inertia ixx="1.0" ixy="0.0" ixz="0.0" iyy="1.0" iyz="0.0" izz="1.0"/>
    </inertial>
    <visual>
      <geometry>
        <cylinder length=".1" radius="0.1"/>
      </geometry>
      <material name="black">
        <color rgba="0 0 0 1"/>
      </material>
    </visual>
    <collision>
      <origin rpy="0 1.57075 1.57075" xyz="0.5 -0.45 0.1"/>
      <geometry>
         <cylinder length=".1" radius="0.1"/>
      </geometry>
    </collision>
  </link>

  <joint name="right_front_wheel_joint" type="continuous">
    <axis xyz="0 0 1"/>
    <parent link="base_link"/>
    <child link="right_front_wheel"/>
    <origin rpy="0 1.57075 1.57075" xyz="0.5 -0.45 0.1"/>
    <limit effort="100" velocity="100"/>
    <joint_properties damping="0.0" friction="0.0"/>
 </joint>

 <link name="left_back_wheel">
    <inertial>
      <origin xyz="-0.5 0.45 0.1"/>
      <mass value="1" />
       <inertia ixx="1.0" ixy="0.0" ixz="0.0" iyy="1.0" iyz="0.0" izz="1.0"/>
    </inertial>
    <visual>
      <geometry>
        <cylinder length=".1" radius="0.1"/>
      </geometry>
      <material name="black">
        <color rgba="0 0 0 1"/>
      </material>
   </visual>
   <collision>
       <origin rpy="0 1.57075 1.57075" xyz="-0.5 0.45 0.1"/>
      <geometry>
         <cylinder length=".1" radius="0.1"/>
      </geometry>
    </collision>
  </link>

  <joint name="left_back_wheel_joint" type="continuous">
    <axis xyz="0 0 1"/>
    <parent link="base_link"/>
    <child link="left_back_wheel"/>
    <origin rpy="0 1.57075 1.57075" xyz="-0.5 0.45 0.1"/>
    <limit effort="100" velocity="100"/>
    <joint_properties damping="0.0" friction="0.0"/>
  </joint>

  <link name="right_back_wheel">
	<inertial>
       <origin xyz="-0.5 -0.45 0.1"/>
       <mass value="1" />
       <inertia ixx="1.0" ixy="0.0" ixz="0.0" iyy="1.0" iyz="0.0" izz="1.0"/>
    </inertial>
    <visual>
      <geometry>
        <cylinder length=".1" radius="0.1"/>
      </geometry>
      <material name="black">
        <color rgba="0 0 0 1"/>
      </material>
   </visual>
   <collision>
      <origin rpy="0 1.57075 1.57075" xyz="-0.5 -0.45 0.1"/>
      <geometry>
         <cylinder length=".1" radius="0.1"/>
      </geometry>
    </collision>
  </link>


  <joint name="right_back_wheel_joint" type="continuous">
    <axis xyz="0 0 1"/>
    <parent link="base_link"/>
    <child link="right_back_wheel"/>
    <origin rpy="0 1.57075 1.57075" xyz="-0.5 -0.45 0.1"/>
    <limit effort="100" velocity="100"/>
    <joint_properties damping="0.0" friction="0.0"/>
  </joint>

  <link name="head">
	<inertial>
      <origin xyz="0.5 0 0.6"/>
      <mass value="1" />
      <inertia ixx="1.0" ixy="0.0" ixz="0.0" iyy="1.0" iyz="0.0" izz="1.0"/>
    </inertial>
    <visual>
      <geometry>
        <box size=".1 .1 .1"/>
      </geometry>
	  <material name="white">
		<color rgba="1 1 1 1"/>
	  </material>
     </visual>
     <collision>
      <origin rpy="0 0 0" xyz="0.5 0 0.6"/>

      <geometry>
         <cylinder length=".1" radius="0.1"/>
      </geometry>
    </collision>
  </link>

  <joint name="tobox" type="fixed">
    <parent link="base_link"/>
    <child link="head"/>
    <origin rpy="0 0 0" xyz="0.5 0 0.6"/>
  </joint>

<link name="laser">
	<inertial>
      <origin xyz="0 0 0"/>
      <mass value="1" />
      <inertia ixx="1.0" ixy="0.0" ixz="0.0" iyy="1.0" iyz="0.0" izz="1.0"/>
    </inertial>
    <visual>
      <geometry>
        <box size=".1 .1 .1"/>
      </geometry>
	  <material name="red">
		<color rgba="1 0 0 1"/>
	  </material>
     </visual>
     <collision>
      <origin xyz="0 0 0"/>
      <geometry>
         <cylinder length=".1" radius="0.1"/>
      </geometry>
    </collision>
  </link>

  <joint name="laser_joint" type="fixed">
    <parent link="base_link"/>
    <child link="laser"/>
    <origin xyz="0 0 0"/>
  </joint>

<!--link name="laser">
 </link>
  <joint name="laser_joint" type="fixed">
    <parent link="base_link"/>
    <child link="laser"/>
    <origin rpy="0 0 4.712388981" xyz="0 0 0"/>
  </joint-->

<!--link name="laser">
 </link>
  <joint name="laser1_joint" type="fixed">
    <parent link="imu"/>
    <child link="laser"/>
    <origin xyz="-1.38289 0.4351 0"/>
  </joint-->

  </xacro:macro>

</robot>
