<?xml version="1.0"?>
<robot name="AGV">
  <link name="base_link">
    <visual>
      <geometry>
        <box size="0.01 0.01 0.01"/>
	</geometry>
	<origin rpy="0 0 0" xyz="-0.30 0 0"/>
    <material name="white">
		<color rgba="5 5 8 1"/>
	</material>
    </visual>
 </link>
  <link name="AGV_body">
    <visual>
      <geometry>
        <box size="0.1 0.5 0.1"/>
	</geometry>
    <material name="white">
		<color rgba=".8 .8 .8 1"/>
	</material>
    </visual>
 </link>
<link name="AGV_tail">
    <visual>
      <geometry>
        <box size="0.6 0.1 0.1"/>
	</geometry>
    <material name="white">
		<color rgba=".8 .8 .8 1"/>
	</material>
    </visual>
 </link>
 <link name="right_wheel">
    <visual>
      <geometry>
        <cylinder length=".1" radius="0.11"/>
      </geometry>
      <material name="black">
        <color rgba="0 0 0 1"/>
      </material>
    </visual>
  </link>
<link name="left_wheel">
    <visual>
      <geometry>
        <cylinder length=".1" radius="0.11"/>
      </geometry>
      <material name="black">
        <color rgba="0 0 0 1"/>
      </material>
    </visual>
  </link>
<link name="tail_wheel">
    <visual>
      <geometry>
        <cylinder length=".1" radius="0.11"/>
      </geometry>
      <material name="black">
        <color rgba="0 0 0 1"/>
      </material>
    </visual>
  </link>
<link name="laser">
    <visual>
      <geometry>
        <cylinder length=".2" radius="0.05"/>
      </geometry>
      <material name="red">
        <color rgba="0 .8 0 1"/>
      </material>
    </visual>
  </link>
 <joint name="AGV_body_joint" type="continuous">
    <axis xyz="0 0 1"/>
    <parent link="base_link"/>
    <child link="AGV_body"/>
    <origin rpy="0 0 0" xyz="0 0 0.1"/>
    <limit effort="100" velocity="100"/>
    <joint_properties damping="0.0" friction="0.0"/>
  </joint>
<joint name="AGV_tail_joint" type="continuous">
    <axis xyz="0 0 1"/>
    <parent link="base_link"/>
    <child link="AGV_tail"/>
    <origin rpy="0 0 0" xyz="-0.25 0 0.1"/>
    <limit effort="100" velocity="100"/>
    <joint_properties damping="0.0" friction="0.0"/>
  </joint>
  <joint name="right_wheel_joint" type="continuous">
    <axis xyz="0 0 1"/>
    <parent link="base_link"/>
    <child link="right_wheel"/>
    <origin rpy="1.57075 0 0" xyz="0 -0.25 0.1"/>
    <limit effort="100" velocity="100"/>
    <joint_properties damping="0.0" friction="0.0"/>
  </joint>
 <joint name="left_wheel_joint" type="continuous">
    <axis xyz="0 0 1"/>
    <parent link="base_link"/>
    <child link="left_wheel"/>
    <origin rpy="1.57075 0 0" xyz="0 0.25 0.1"/>
    <limit effort="100" velocity="100"/>
    <joint_properties damping="0.0" friction="0.0"/>
  </joint>
<joint name="tail_wheel_joint" type="continuous">
    <axis xyz="0 0 1"/>
    <parent link="base_link"/>
    <child link="tail_wheel"/>
    <origin rpy="1.57075 0 0" xyz="-0.6 0 0.1"/>
    <limit effort="100" velocity="100"/>
    <joint_properties damping="0.0" friction="0.0"/>
  </joint>

<joint name="laser_scan_joint" type="continuous">
    <axis xyz="0 0 1"/>
    <parent link="base_link"/>
    <child link="laser"/>
    <origin rpy="0 0 0" xyz="0 0 0.2"/>
    <limit effort="100" velocity="100"/>
    <joint_properties damping="0.0" friction="0.0"/>
  </joint>
</robot>

